# Go的异常处理

[//]: # (__author__ = "Clark Aaron")

Go提供一个Error的标准接口，使用panic引发恐慌，recover捕获恐慌；通过错误接口提供了一个错误处理机制。

## Error

* 错误为error，一个简单的内置接口：

  ```go
  type error interface {
      Error() string
  }
  ```

### Error的应用

* 自定义错误：

  ```go
  // PathError records an error and the operation and
  // file path that caused it.
  type PathError struct {
      Op string    // "open", "unlink", etc.
      Path string  // The associated file.
      Err error    // Returned by the system call.
  }

  func (e *PathError) Error() string {
      return e.Op + " " + e.Path + ": " + e.Err.Error()
  }
  ```

## Panic

`panic()`是一个内置函数，创建一个运行时错误，从而停止程序；该函数接收一个任意类型的参数，通常为字符串，以便在程序结束时输出；在触发一个`panic`时，将会立即停止当前函数的执行，并展开goroutine的堆栈，在此过程中将运行任何`defer`函数，如果unwind到达goroutine堆栈的顶部，程序就会终止。

* 异常抛出：

  ```go
  panic(<errMessage>)
  ```

  > Note：返回的是一个error接口。

## Recover

`recover()`是一个内置函数，能够停止unwinding并返回panic的参数，因为unwind时唯一运行的代码是在延迟函数中，所以`recover`只在延迟函数中有用。恢复的一个应用程序是关闭服务器中失败的goroutine，而不杀死其他正在执行的goroutine。

* 异常捕获：

  ```go
  func server(workChan <-chan *Work) {
    for work := range workChan {
        go safelyDo(work)
      }
  }

  func safelyDo(work *Work) {
      defer func() {
          if err := recover(); err != nil {
              log.Println("work failed:", err)
          }
      }()
      do(work)
  }
  ```

  > Note：利用recover处理panic异常必须在defer中调用的函数中才有效，否则recover无法捕获panic异常，无法防止panic扩散；且defer必须在panic之前定义。
